<?xml version="1.0"?>
<robot name="balance">

  <material name="white">
    <color rgba="1 1 1 1"/>
  </material>

  <material name="black">
    <color rgba="0.2 0.2 0.2 1"/>
  </material>

  <link name="torso">
    <visual>
      <geometry>
      <!-- width (x), depth (y), height (z) -->
        <box size="0.215 0.0625 0.135"/>
      </geometry>
      <origin rpy="0 0 0" xyz="0.0 0.0 0.05"/>
      <material name="white"/>
    </visual>
    <collision>
      <geometry>
        <box size="0.215 0.0625 0.135"/>
      </geometry>
      <origin rpy="0 0 0" xyz="0.0 0.0 0.05"/>
      <contact_coefficients mu="1" />
    </collision>
    <inertial>
      <mass value="0.7517"/>
      <inertia ixx="0.00138633838541667" ixy="0.0" ixz="0.0" iyy="0.00403725541666667" iyz="0.0" izz="0.00314030505208333"/>
      <origin rpy="0 0 0" xyz="0 0.0 0.1"/>
    </inertial>
  </link>

  <link name="l_wheel">
    <visual>
      <geometry>
        <cylinder length="0.025" radius="0.0325"/>
      </geometry>
      <origin rpy="0 1.5707963 0" xyz="0 0 0"/>
      <material name="black"/>
    </visual>
    <collision>
      <geometry>
        <cylinder length="0.025" radius="0.0325"/>
      </geometry>
      <origin rpy="0 1.5707963 0" xyz="0 0 0"/>
      <contact_coefficients mu="0.7" />
    </collision>
    <inertial>
      <mass value="0.0385"/>
      <inertia ixx="0.0000121716145833333" ixy="0.0" ixz="0.0" iyy="0.0000121716145833333" iyz="0.0" izz="0.0000203328125"/>
      <origin rpy="0 0 0" xyz="0 0 0"/>
    </inertial>
  </link>

  <link name="r_wheel">
    <visual>
      <geometry>
        <cylinder length="0.025" radius="0.0325"/>
      </geometry>
      <origin rpy="0 1.5707963 0" xyz="0 0 0"/>
      <material name="black"/>
    </visual>
    <collision>
      <geometry>
        <cylinder length="0.025" radius="0.0325"/>
      </geometry>
      <origin rpy="0 1.5707963 0" xyz="0 0 0"/>
      <contact_coefficients mu="0.7" />
    </collision>
    <inertial>
      <mass value="0.0385"/>
      <inertia ixx="0.0000121716145833333" ixy="0.0" ixz="0.0" iyy="0.0000121716145833333" iyz="0.0" izz="0.0000203328125"/>
      <origin rpy="0 0 0" xyz="0 0 0"/>
    </inertial>
  </link>

  <joint name="torso_l_wheel" type="continuous">
    <parent link="torso"/>
    <child link="l_wheel"/>
    <axis xyz="-1 0 0"/>
    <!-- <limit effort="1000.0" lower="0.0" upper="0.548" velocity="0.0"/> -->
    <origin rpy="0 0 0" xyz="-0.12 0.0 0.0"/>
  </joint>

  <joint name="torso_r_wheel" type="continuous">
    <parent link="torso"/>
    <child link="r_wheel"/>
    <axis xyz="1 0 0"/>
   <!-- <limit effort="1000.0" lower="0.0" upper="0.548" velocity="0.0"/> -->
   <origin rpy="0 0 0" xyz="0.12 0.0 0.0"/>
  </joint>

</robot>